<?xml version="1.0" ?>
<robot name="door">
	<link name="base_link" />

	<link name="door">
		<inertial>
			<origin xyz="-0.00724 0.441 1.029" rpy="0 0 0" />
			<mass value="5."/>
			<inertia ixx="1" ixy="0" ixz="0"
			iyy="1" iyz="0"
			izz="1" />
		</inertial>
		<visual>
			<geometry>
				<mesh filename="file://@CATKIN_PACKAGE_SHARE_DESTINATION@/meshes//1dof.dae" />
			</geometry>
		</visual>
	</link>

	<joint name="door" type="revolute">
		<axis xyz="0 0 1"/>
		<limit effort="0" velocity="100" lower="-3.141592653589793" upper="3.141592653589793" />
		<parent link="base_link" />
		<child link="door" />
		<origin rpy="0.0 0.0 0.0" xyz="0.0 0.0 0.0" />
	</joint>
</robot>
